Workbook

Sheet LEEME
A1: LEEME — base_datos_caso2.xlsx
A4: Campo | B4: Descripción
A5: Propósito | B5: Base de datos del Caso 2 (terremoto del 10-ago-2026): demanda, candidatos, costos, coordenadas y distancias por carretera.
A6: Cómo se genera | B6: notebooks/01_datos_coordenadas_distancias.ipynb a partir de data/raw/base_datos_caso2_original.xlsx (fórmulas del grupo intactas).
A7: Hojas del grupo | B7: Parametros (fuente única de supuestos; P25–P27 agregados), Candidatos, Presupuesto, Demanda.
A8: Hojas agregadas | B8: Coordenadas, Distancias_km (matriz final), Distancias_OSRM, Alcance_180km, Control_distancias, Control_140_160km, Albergados_observados, Fuentes, Registro_cambios, Calidad_datos, Diccionario.
A9: Calidad de datos | B9: Hoja Calidad_datos: pruebas PASS / WARNING / FAIL sobre los datos de entrada (objetivo 0 FAIL); misma tabla que results/tablas/calidad_datos.csv.
A10: Tipos de dato | B10: Real = dato de fuente o del enunciado; Calculado = derivado con fórmula; Supuesto = decisión del grupo (ver hoja Diccionario).
A11: Unidades | B11: Costos en COP; distancias en km por carretera; capacidades y demanda en personas.
A12: Supuestos clave | B12: c_f = 200.000 COP/plaza-mes; φ = 0,85/1,00/1,15; f = 10 %; v = 60.000 COP (redondeo de 29.730 + 29.730).
A13: Decisiones metodológicas | B13: 17 candidatos con 10 pequeños (sin ellos no se llega a 15); presupuesto sobre el costo total; matriz combinada Google Maps/OSRM. Alternativas solo como sensibilidad.
A14: Fuentes | B14: Hoja Fuentes (ID, URL, tipo, uso y verificación) y docs/bibliografia.md.

Sheet Parametros
A1: Parámetros y registro de supuestos – Caso 2: Terremoto en Colombia (10-ago-2026)
A2: Leyenda: texto azul = valor de entrada editable · fondo amarillo = supuesto provisional clave (sensibilidad pendiente) · Tipo: Real (dato de fuente o del enunciado), Calculado, Supuesto.
A4: ID | B4: Parámetro | C4: Valor | D4: Unidad | E4: Tipo | F4: Fuente / justificación
A5: P01 | B5: Costo fijo por plaza-mes (c_f) | C5: 200000 | D5: COP/plaza-mes | E5: Supuesto | F5: PROVISIONAL. Supuesto propio: ≈40–55% del apoyo UNGRD por persona (Cronista 02-sep-2026: $787.907–1.050.543 por hogar-mes). Sin fuente colombiana de costo de operación de campamentos.
A6: P02 | B6: Duración de referencia (T) | C6: 3 | D6: meses | E6: Supuesto | F6: Igual al periodo de 3 pagos del apoyo económico UNGRD (Cronista 02-sep-2026).
A7: P03 | B7: Costo variable por persona (v) | C7: 60000 | D7: COP/persona | E7: Supuesto | F7: Kit de alimentación ($29.730) + kit de aseo ($29.730), gama alta, precios minoristas D1 (El Tiempo, 14-ago-2026). No es precio institucional. La suma es 59.460: v = 60.000 es un redondeo declarado (+540, ver P27).
A8: P04 | B8: Costo de transporte | C8: 500 | D8: COP/km·persona | E8: Real | F8: Enunciado del caso (costo lineal).
A9: P05 | B9: Factor de escala – Grande | C9: 0.85 | D9: adimensional | E9: Supuesto | F9: Economías de escala en campamentos grandes.
A10: P06 | B10: Factor de escala – Intermedia | C10: 1 | D10: adimensional | E10: Supuesto | F10: Categoría de referencia.
A11: P07 | B11: Factor de escala – Pequeña | C11: 1.15 | D11: adimensional | E11: Supuesto | F11: Deseconomías de escala en campamentos pequeños.
A12: P08 | B12: Capacidad – Grande | C12: 3000 | D12: personas | E12: Real | F12: Enunciado del caso.
A13: P09 | B13: Capacidad – Intermedia | C13: 1000 | D13: personas | E13: Real | F13: Enunciado del caso.
A14: P10 | B14: Capacidad – Pequeña | C14: 500 | D14: personas | E14: Real | F14: Enunciado del caso.
A15: P11 | B15: Corte población Grande (≥) | C15: 200000 | D15: habitantes | E15: Supuesto | F15: Corte propio (decisión 6).
A16: P12 | B16: Corte población Intermedia (≥) | C16: 100000 | D16: habitantes | E16: Supuesto | F16: Sigue el umbral de 100.000 del Sistema de Ciudades del DNP (verificado solo en fuente secundaria).
... A30: P26 | B30: Costo kit de aseo (por persona) | C30: 29730 | D30: COP/persona | E30: Real (prensa) | F30: F06: El Tiempo 14-ago-2026 (precio minorista D1)
A31: P27 | B31: Ajuste por redondeo de v (P03 − P25 − P26) | C31: =C7-C29-C30 -> 540 | D31: COP/persona | E31: Calculado | F31: P03 = 60.000 es el redondeo declarado de 59.460 (+0,9 %)

Sheet Candidatos
A1: Sitios candidatos y costos – 17 candidatos + 1 reserva
A2: Candidatos pequeños (10 de 17): decisión adoptada por el grupo (excluirlos es solo una sensibilidad del notebook 02). Coordenadas DIVIPOLA (30-sep-2026) en la hoja Coordenadas; matriz final de distancias (OSRM + Google Maps en 164 pares) en Distancias_km.
A4: Identif. | B4: Identif. | C4: Identif. | D4: Identif. | E4: Supuesto | F4: Real | G4: Real | H4: Real | I4: Calculado | J4: Calculado | K4: Real | L4: Supuesto | M4: Calculado | N4: Calculado | O4: Supuesto | P4: Calculado
A5: ID | B5: DIVIPOLA | C5: Municipio | D5: Departamento | E5: Rol | F5: Población DANE 2026 | G5: NH (RUD) | H5: Personas registradas (RUD) | I5: % registrado | J5: Categoría | K5: Capacidad K_j | L5: Factor escala | M5: Costo fijo por plaza (T meses) | N5: Costo fijo f_j | O5: Costo variable v_j | P5: Filtros S2/S7
A6: C01 | B6: 76520 | C6: Palmira | D6: Valle del Cauca | E6: Candidato | F6: 382703 | G6: 74 | H6: 2411 | I6: =H6/F6 -> 0.0062999245 | J6: =IF(F6>=Parametros!$C$15,"Grande",IF(F6>=Parametros!$C$16,"Intermedia","Pequeña")) -> Grande | K6: =IF(J6="Grande",Parametros!$C$12,IF(J6="Intermedia",Parametros!$C$13,Parametros!$C$14)) -> 3000 | L6: =IF(J6="Grande",Parametros!$C$9,IF(J6="Intermedia",Parametros!$C$10,Parametros!$C$11)) -> 0.85 | M6: =Parametros!$C$5*Parametros!$C$6*L6 -> 510000 | N6: =K6*M6 -> 1530000000 | O6: =Parametros!$C$7 -> 60000 | P6: =IF(AND(G6<Parametros!$C$17,I6<Parametros!$C$18),"Cumple","No cumple") -> Cumple
A7: C02 | B7: 76834 | C7: Tuluá | D7: Valle del Cauca | E7: Candidato | F7: 225868 | G7: 66 | H7: 2582 | I7: =H7/F7 -> 0.011431456 | J7: =IF(F7>=Parametros!$C$15,"Grande",IF(F7>=Parametros!$C$16,"Intermedia","Pequeña")) -> Grande | K7: =IF(J7="Grande",Parametros!$C$12,IF(J7="Intermedia",Parametros!$C$13,Parametros!$C$14)) -> 3000 | L7: =IF(J7="Grande",Parametros!$C$9,IF(J7="Intermedia",Parametros!$C$10,Parametros!$C$11)) -> 0.85 | M7: =Parametros!$C$5*Parametros!$C$6*L7 -> 510000 | N7: =K7*M7 -> 1530000000 | O7: =Parametros!$C$7 -> 60000 | P7: =IF(AND(G7<Parametros!$C$17,I7<Parametros!$C$18),"Cumple","No cumple") -> Cumple
A8: C03 | B8: 76364 | C8: Jamundí | D8: Valle del Cauca | E8: Candidato | F8: 196875 | G8: 161 | H8: 4396 | I8: =H8/F8 -> 0.022328889 | J8: =IF(F8>=Parametros!$C$15,"Grande",IF(F8>=Parametros!$C$16,"Intermedia","Pequeña")) -> Intermedia | K8: =IF(J8="Grande",Parametros!$C$12,IF(J8="Intermedia",Parametros!$C$13,Parametros!$C$14)) -> 1000 | L8: =IF(J8="Grande",Parametros!$C$9,IF(J8="Intermedia",Parametros!$C$10,Parametros!$C$11)) -> 1 | M8: =Parametros!$C$5*Parametros!$C$6*L8 -> 600000 | N8: =K8*M8 -> 600000000 | O8: =Parametros!$C$7 -> 60000 | P8: =IF(AND(G8<Parametros!$C$17,I8<Parametros!$C$18),"Cumple","No cumple") -> Cumple
A9: C04 | B9: 76147 | C9: Cartago | D9: Valle del Cauca | E9: Candidato | F9: 144206 | G9: 207 | H9: 2490 | I9: =H9/F9 -> 0.017266965 | J9: =IF(F9>=Parametros!$C$15,"Grande",IF(F9>=Parametros!$C$16,"Intermedia","Pequeña")) -> Intermedia | K9: =IF(J9="Grande",Parametros!$C$12,IF(J9="Intermedia",Parametros!$C$13,Parametros!$C$14)) -> 1000 | L9: =IF(J9="Grande",Parametros!$C$9,IF(J9="Intermedia",Parametros!$C$10,Parametros!$C$11)) -> 1 | M9: =Parametros!$C$5*Parametros!$C$6*L9 -> 600000 | N9: =K9*M9 -> 600000000 | O9: =Parametros!$C$7 -> 60000 | P9: =IF(AND(G9<Parametros!$C$17,I9<Parametros!$C$18),"Cumple","No cumple") -> Cumple
A10: C05 | B10: 76111 | C10: Guadalajara de Buga | D10: Valle del Cauca | E10: Candidato | F10: 132250 | G10: 80 | H10: 1554 | I10: =H10/F10 -> 0.011750473 | J10: =IF(F10>=Parametros!$C$15,"Grande",IF(F10>=Parametros!$C$16,"Intermedia","Pequeña")) -> Intermedia | K10: =IF(J10="Grande",Parametros!$C$12,IF(J10="Intermedia",Parametros!$C$13,Parametros!$C$14)) -> 1000 | L10: =IF(J10="Grande",Parametros!$C$9,IF(J10="Intermedia",Parametros!$C$10,Parametros!$C$11)) -> 1 | M10: =Parametros!$C$5*Parametros!$C$6*L10 -> 600000 | N10: =K10*M10 -> 600000000 | O10: =Parametros!$C$7 -> 60000 | P10: =IF(AND(G10<Parametros!$C$17,I10<Parametros!$C$18),"Cumple","No cumple") -> Cumple
A11: C06 | B11: 76130 | C11: Candelaria | D11: Valle del Cauca | E11: Candidato | F11: 115933 | G11: 22 | H11: 573 | I11: =H11/F11 -> 0.0049425099 | J11: =IF(F11>=Parametros!$C$15,"Grande",IF(F11>=Parametros!$C$16,"Intermedia","Pequeña")) -> Intermedia | K11: =IF(J11="Grande",Parametros!$C$12,IF(J11="Intermedia",Parametros!$C$13,Parametros!$C$14)) -> 1000 | L11: =IF(J11="Grande",Parametros!$C$9,IF(J11="Intermedia",Parametros!$C$10,Parametros!$C$11)) -> 1 | M11: =Parametros!$C$5*Parametros!$C$6*L11 -> 600000 | N11: =K11*M11 -> 600000000 | O11: =Parametros!$C$7 -> 60000 | P11: =IF(AND(G11<Parametros!$C$17,I11<Parametros!$C$18),"Cumple","No cumple") -> Cumple
A12: C07 | B12: 76892 | C12: Yumbo | D12: Valle del Cauca | E12: Candidato | F12: 115667 | G12: 158 | H12: 2388 | I12: =H12/F12 -> 0.020645474 | J12: =IF(F12>=Parametros!$C$15,"Grande",IF(F12>=Parametros!$C$16,"Intermedia","Pequeña")) -> Intermedia | K12: =IF(J12="Grande",Parametros!$C$12,IF(J12="Intermedia",Parametros!$C$13,Parametros!$C$14)) -> 1000 | L12: =IF(J12="Grande",Parametros!$C$9,IF(J12="Intermedia",Parametros!$C$10,Parametros!$C$11)) -> 1 | M12: =Parametros!$C$5*Parametros!$C$6*L12 -> 600000 | N12: =K12*M12 -> 600000000 | O12: =Parametros!$C$7 -> 60000 | P12: =IF(AND(G12<Parametros!$C$17,I12<Parametros!$C$18),"Cumple","No cumple") -> Cumple
A13: C08 | B13: 76275 | C13: Florida | D13: Valle del Cauca | E13: Candidato | F13: 57017 | G13: 19 | H13: 986 | I13: =H13/F13 -> 0.017293088 | J13: =IF(F13>=Parametros!$C$15,"Grande",IF(F13>=Parametros!$C$16,"Intermedia","Pequeña")) -> Pequeña | K13: =IF(J13="Grande",Parametros!$C$12,IF(J13="Intermedia",Parametros!$C$13,Parametros!$C$14)) -> 500 | L13: =IF(J13="Grande",Parametros!$C$9,IF(J13="Intermedia",Parametros!$C$10,Parametros!$C$11)) -> 1.15 | M13: =Parametros!$C$5*Parametros!$C$6*L13 -> 690000 | N13: =K13*M13 -> 345000000 | O13: =Parametros!$C$7 -> 60000 | P13: =IF(AND(G13<Parametros!$C$17,I13<Parametros!$C$18),"Cumple","No cumple") -> Cumple
A14: C09 | B14: 76248 | C14: El Cerrito | D14: Valle del Cauca | E14: Candidato | F14: 56397 | G14: 21 | H14: 537 | I14: =H14/F14 -> 0.0095217831 | J14: =IF(F14>=Parametros!$C$15,"Grande",IF(F14>=Parametros!$C$16,"Intermedia","Pequeña")) -> Pequeña | K14: =IF(J14="Grande",Parametros!$C$12,IF(J14="Intermedia",Parametros!$C$13,Parametros!$C$14)) -> 500 | L14: =IF(J14="Grande",Parametros!$C$9,IF(J14="Intermedia",Parametros!$C$10,Parametros!$C$11)) -> 1.15 | M14: =Parametros!$C$5*Parametros!$C$6*L14 -> 690000 | N14: =K14*M14 -> 345000000 | O14: =Parametros!$C$7 -> 60000 | P14: =IF(AND(G14<Parametros!$C$17,I14<Parametros!$C$18),"Cumple","No cumple") -> Cumple
A15: C10 | B15: 76563 | C15: Pradera | D15: Valle del Cauca | E15: Candidato | F15: 50067 | G15: 16 | H15: 742 | I15: =H15/F15 -> 0.014820141 | J15: =IF(F15>=Parametros!$C$15,"Grande",IF(F15>=Parametros!$C$16,"Intermedia","Pequeña")) -> Pequeña | K15: =IF(J15="Grande",Parametros!$C$12,IF(J15="Intermedia",Parametros!$C$13,Parametros!$C$14)) -> 500 | L15: =IF(J15="Grande",Parametros!$C$9,IF(J15="Intermedia",Parametros!$C$10,Parametros!$C$11)) -> 1.15 | M15: =Parametros!$C$5*Parametros!$C$6*L15 -> 690000 | N15: =K15*M15 -> 345000000 | O15: =Parametros!$C$7 -> 60000 | P15: =IF(AND(G15<Parametros!$C$17,I15<Parametros!$C$18),"Cumple","No cumple") -> Cumple
A16: C11 | B16: 76318 | C16: Guacarí | D16: Valle del Cauca | E16: Candidato | F16: 34739 | G16: 47 | H16: 373 | I16: =H16/F16 -> 0.010737212 | J16: =IF(F16>=Parametros!$C$15,"Grande",IF(F16>=Parametros!$C$16,"Intermedia","Pequeña")) -> Pequeña | K16: =IF(J16="Grande",Parametros!$C$12,IF(J16="Intermedia",Parametros!$C$13,Parametros!$C$14)) -> 500 | L16: =IF(J16="Grande",Parametros!$C$9,IF(J16="Intermedia",Parametros!$C$10,Parametros!$C$11)) -> 1.15 | M16: =Parametros!$C$5*Parametros!$C$6*L16 -> 690000 | N16: =K16*M16 -> 345000000 | O16: =Parametros!$C$7 -> 60000 | P16: =IF(AND(G16<Parametros!$C$17,I16<Parametros!$C$18),"Cumple","No cumple") -> Cumple
A17: C12 | B17: 76306 | C17: Ginebra | D17: Valle del Cauca | E17: Candidato | F17: 24545 | G17: 14 | H17: 740 | I17: =H17/F17 -> 0.030148706 | J17: =IF(F17>=Parametros!$C$15,"Grande",IF(F17>=Parametros!$C$16,"Intermedia","Pequeña")) -> Pequeña | K17: =IF(J17="Grande",Parametros!$C$12,IF(J17="Intermedia",Parametros!$C$13,Parametros!$C$14)) -> 500 | L17: =IF(J17="Grande",Parametros!$C$9,IF(J17="Intermedia",Parametros!$C$10,Parametros!$C$11)) -> 1.15 | M17: =Parametros!$C$5*Parametros!$C$6*L17 -> 690000 | N17: =K17*M17 -> 345000000 | O17: =Parametros!$C$7 -> 60000 | P17: =IF(AND(G17<Parametros!$C$17,I17<Parametros!$C$18),"Cumple","No cumple") -> Cumple
... A22: C17 | B22: 17380 | C22: La Dorada | D22: Caldas | E22: Candidato | F22: 71480 | G22: 3 | H22: 147 | I22: =H22/F22 -> 0.0020565193 | J22: =IF(F22>=Parametros!$C$15,"Grande",IF(F22>=Parametros!$C$16,"Intermedia","Pequeña")) -> Pequeña | K22: =IF(J22="Grande",Parametros!$C$12,IF(J22="Intermedia",Parametros!$C$13,Parametros!$C$14)) -> 500 | L22: =IF(J22="Grande",Parametros!$C$9,IF(J22="Intermedia",Parametros!$C$10,Parametros!$C$11)) -> 1.15 | M22: =Parametros!$C$5*Parametros!$C$6*L22 -> 690000 | N22: =K22*M22 -> 345000000 | O22: =Parametros!$C$7 -> 60000 | P22: =IF(AND(G22<Parametros!$C$17,I22<Parametros!$C$18),"Cumple","No cumple") -> Cumple
A24: Reserva (no entra al cálculo del presupuesto ni a los 17 candidatos base):
A25: R01 | B25: 63401 | C25: La Tebaida | D25: Quindío | E25: Reserva | F25: 33758 | G25: 95 | H25: 2773 | I25: =H25/F25 -> 0.082143492 | J25: =IF(F25>=Parametros!$C$15,"Grande",IF(F25>=Parametros!$C$16,"Intermedia","Pequeña")) -> Pequeña | K25: =IF(J25="Grande",Parametros!$C$12,IF(J25="Intermedia",Parametros!$C$13,Parametros!$C$14)) -> 500 | L25: =IF(J25="Grande",Parametros!$C$9,IF(J25="Intermedia",Parametros!$C$10,Parametros!$C$11)) -> 1.15 | M25: =Parametros!$C$5*Parametros!$C$6*L25 -> 690000 | N25: =K25*M25 -> 345000000 | O25: =Parametros!$C$7 -> 60000 | P25: =IF(AND(G25<Parametros!$C$17,I25<Parametros!$C$18),"Cumple","No cumple") -> No cumple
A27: Notas: (1) NH y personas registradas provienen del consolidado del RUD (corte 17-sep-2026), agregador secundario datosdelterremoto.org. (2) Población: DANE, Proyecciones municipales 2018-2042. (3) La Tebaida no cumple el filtro S7 (8,2%); se mantiene como reserva por su cercanía a Armenia.

Sheet Presupuesto
A1: Presupuesto y escenarios (COP)
A3: Σ costo fijo de los 10 campamentos candidatos más grandes | B3: =SUMPRODUCT(LARGE(Candidatos!$N$6:$N$22,{1,2,3,4,5,6,7,8,9,10})) -> 7095000000 | C3: Calculado
A4: % del enunciado | B4: =Parametros!$C$21 -> 0.5 | C4: Real
A5: Presupuesto BASE | B5: =B3*B4 -> 3547500000 | C5: Calculado
A6: Presupuesto escenario A (reducción P18) | B6: =B5*(1-Parametros!$C$22) -> 3015375000 | C6: Calculado
A7: Presupuesto escenario B (reducción P19) | B7: =B5*(1-Parametros!$C$23) -> 2483250000 | C7: Calculado
A8: Σ costo fijo de los 17 candidatos (abrir todos) | B8: =SUM(Candidatos!$N$6:$N$22) -> 9510000000 | C8: Calculado
A9: Capacidad total de los 17 candidatos (personas) | B9: =SUM(Candidatos!$K$6:$K$22) -> 16000 | C9: Calculado
A10: Presupuesto base / costo de abrir todos | B10: =B5/B8 -> 0.37302839 | C10: Calculado
A13: Sensibilidad del costo fijo por plaza-mes (c_f). Los costos fijos y el presupuesto escalan linealmente con c_f.
A14: c_f (COP/plaza-mes) | B14: Costo fijo Grande | C14: Costo fijo Intermedia | D14: Costo fijo Pequeña | E14: Presupuesto BASE | F14: Presupuesto A | G14: Presupuesto B
A15: 100000 | B15: =Parametros!$C$12*A15*Parametros!$C$6*Parametros!$C$9 -> 765000000 | C15: =Parametros!$C$13*A15*Parametros!$C$6*Parametros!$C$10 -> 300000000 | D15: =Parametros!$C$14*A15*Parametros!$C$6*Parametros!$C$11 -> 172500000 | E15: =$B$5*A15/Parametros!$C$5 -> 1773750000 | F15: =E15*(1-Parametros!$C$22) -> 1507687500 | G15: =E15*(1-Parametros!$C$23) -> 1241625000
A16: 150000 | B16: =Parametros!$C$12*A16*Parametros!$C$6*Parametros!$C$9 -> 1147500000 | C16: =Parametros!$C$13*A16*Parametros!$C$6*Parametros!$C$10 -> 450000000 | D16: =Parametros!$C$14*A16*Parametros!$C$6*Parametros!$C$11 -> 258750000 | E16: =$B$5*A16/Parametros!$C$5 -> 2660625000 | F16: =E16*(1-Parametros!$C$22) -> 2261531250 | G16: =E16*(1-Parametros!$C$23) -> 1862437500
A17: 200000 | B17: =Parametros!$C$12*A17*Parametros!$C$6*Parametros!$C$9 -> 1530000000 | C17: =Parametros!$C$13*A17*Parametros!$C$6*Parametros!$C$10 -> 600000000 | D17: =Parametros!$C$14*A17*Parametros!$C$6*Parametros!$C$11 -> 345000000 | E17: =$B$5*A17/Parametros!$C$5 -> 3547500000 | F17: =E17*(1-Parametros!$C$22) -> 3015375000 | G17: =E17*(1-Parametros!$C$23) -> 2483250000
A18: 250000 | B18: =Parametros!$C$12*A18*Parametros!$C$6*Parametros!$C$9 -> 1912500000 | C18: =Parametros!$C$13*A18*Parametros!$C$6*Parametros!$C$10 -> 750000000 | D18: =Parametros!$C$14*A18*Parametros!$C$6*Parametros!$C$11 -> 431250000 | E18: =$B$5*A18/Parametros!$C$5 -> 4434375000 | F18: =E18*(1-Parametros!$C$22) -> 3769218750 | G18: =E18*(1-Parametros!$C$23) -> 3104062500
A19: 300000 | B19: =Parametros!$C$12*A19*Parametros!$C$6*Parametros!$C$9 -> 2295000000 | C19: =Parametros!$C$13*A19*Parametros!$C$6*Parametros!$C$10 -> 900000000 | D19: =Parametros!$C$14*A19*Parametros!$C$6*Parametros!$C$11 -> 517500000 | E19: =$B$5*A19/Parametros!$C$5 -> 5321250000 | F19: =E19*(1-Parametros!$C$22) -> 4523062500 | G19: =E19*(1-Parametros!$C$23) -> 3724875000
A20: 400000 | B20: =Parametros!$C$12*A20*Parametros!$C$6*Parametros!$C$9 -> 3060000000 | C20: =Parametros!$C$13*A20*Parametros!$C$6*Parametros!$C$10 -> 1200000000 | D20: =Parametros!$C$14*A20*Parametros!$C$6*Parametros!$C$11 -> 690000000 | E20: =$B$5*A20/Parametros!$C$5 -> 7095000000 | F20: =E20*(1-Parametros!$C$22) -> 6030750000 | G20: =E20*(1-Parametros!$C$23) -> 4966500000
A22: Nota: la fila con c_f = P01 reproduce el presupuesto base. El escalamiento lineal del presupuesto es válido porque todo costo fijo es proporcional a c_f.

Sheet Demanda
A1: Puntos de demanda – 29 municipios (NH ≥ 400, corte RUD 17-sep-2026)
A3: Identif. | B3: Identif. | C3: Identif. | D3: Real | E3: Real | F3: Real | G3: Real | H3: Calculado | I3: Calculado | J3: Calculado | K3: Calculado | L3: Calculado | M3: Calculado | N3: Calculado | O3: Calculado | P3: Real
A4: DIVIPOLA | B4: Municipio | C4: Departamento | D4: Población DANE 2026 | E4: NH (RUD) | F4: Familias (RUD) | G4: Personas registradas (RUD) | H4: Hogar RUD (pers/fam) | I4: Personas en NH | J4: d_i f=2% | K4: d_i f=5% | L4: d_i f=10% (BASE) | M4: d_i f=13% | N4: d_i f=10% hogar 3,0 | O4: % registrado | P4: Calidad dato RUD
A5: 66001 | B5: Pereira | C5: Risaralda | D5: 487820 | E5: 23873 | F5: 47211 | G5: 110882 | H5: =G5/F5 -> 2.3486476 | I5: =E5*H5 -> 56069.263 | J5: =ROUND(I5*Parametros!$C$25,0) -> 1121 | K5: =ROUND(I5*Parametros!$C$26,0) -> 2803 | L5: =ROUND(I5*Parametros!$C$24,0) -> 5607 | M5: =ROUND(I5*Parametros!$C$27,0) -> 7289 | N5: =ROUND(E5*Parametros!$C$28*Parametros!$C$24,0) -> 7162 | O5: =G5/D5 -> 0.22730105 | P5: F
A6: 76001 | B6: Cali | C6: Valle del Cauca | D6: 2269983 | E6: 21309 | F6: 45138 | G6: 97337 | H6: =G6/F6 -> 2.1564314 | I6: =E6*H6 -> 45951.396 | J6: =ROUND(I6*Parametros!$C$25,0) -> 919 | K6: =ROUND(I6*Parametros!$C$26,0) -> 2298 | L6: =ROUND(I6*Parametros!$C$24,0) -> 4595 | M6: =ROUND(I6*Parametros!$C$27,0) -> 5974 | N6: =ROUND(E6*Parametros!$C$28*Parametros!$C$24,0) -> 6393 | O6: =G6/D6 -> 0.042880057 | P6: F
A7: 76109 | B7: Buenaventura | C7: Valle del Cauca | D7: 335217 | E7: 9557 | F7: 31654 | G7: 67590 | H7: =G7/F7 -> 2.1352752 | I7: =E7*H7 -> 20406.825 | J7: =ROUND(I7*Parametros!$C$25,0) -> 408 | K7: =ROUND(I7*Parametros!$C$26,0) -> 1020 | L7: =ROUND(I7*Parametros!$C$24,0) -> 2041 | M7: =ROUND(I7*Parametros!$C$27,0) -> 2653 | N7: =ROUND(E7*Parametros!$C$28*Parametros!$C$24,0) -> 2867 | O7: =G7/D7 -> 0.20163059 | P7: F
A8: 63001 | B8: Armenia | C8: Quindío | D8: 307103 | E8: 7270 | F8: 21935 | G8: 41197 | H8: =G8/F8 -> 1.87814 | I8: =E8*H8 -> 13654.078 | J8: =ROUND(I8*Parametros!$C$25,0) -> 273 | K8: =ROUND(I8*Parametros!$C$26,0) -> 683 | L8: =ROUND(I8*Parametros!$C$24,0) -> 1365 | M8: =ROUND(I8*Parametros!$C$27,0) -> 1775 | N8: =ROUND(E8*Parametros!$C$28*Parametros!$C$24,0) -> 2181 | O8: =G8/D8 -> 0.13414718 | P8: F
A9: 66170 | B9: Dosquebradas | C9: Risaralda | D9: 246388 | E9: 4179 | F9: 8116 | G9: 17742 | H9: =G9/F9 -> 2.1860522 | I9: =E9*H9 -> 9135.5123 | J9: =ROUND(I9*Parametros!$C$25,0) -> 183 | K9: =ROUND(I9*Parametros!$C$26,0) -> 457 | L9: =ROUND(I9*Parametros!$C$24,0) -> 914 | M9: =ROUND(I9*Parametros!$C$27,0) -> 1188 | N9: =ROUND(E9*Parametros!$C$28*Parametros!$C$24,0) -> 1254 | O9: =G9/D9 -> 0.072008377 | P9: F
A10: 17001 | B10: Manizales | C10: Caldas | D10: 475690 | E10: 4590 | F10: 9125 | G10: 14359 | H10: =G10/F10 -> 1.573589 | I10: =E10*H10 -> 7222.7737 | J10: =ROUND(I10*Parametros!$C$25,0) -> 144 | K10: =ROUND(I10*Parametros!$C$26,0) -> 361 | L10: =ROUND(I10*Parametros!$C$24,0) -> 722 | M10: =ROUND(I10*Parametros!$C$27,0) -> 939 | N10: =ROUND(E10*Parametros!$C$28*Parametros!$C$24,0) -> 1377 | O10: =G10/D10 -> 0.030185625 | P10: F
A11: 66682 | B11: Santa Rosa de Cabal | C11: Risaralda | D11: 84054 | E11: 1904 | F11: 5202 | G11: 11899 | H11: =G11/F11 -> 2.2873895 | I11: =E11*H11 -> 4355.1895 | J11: =ROUND(I11*Parametros!$C$25,0) -> 87 | K11: =ROUND(I11*Parametros!$C$26,0) -> 218 | L11: =ROUND(I11*Parametros!$C$24,0) -> 436 | M11: =ROUND(I11*Parametros!$C$27,0) -> 566 | N11: =ROUND(E11*Parametros!$C$28*Parametros!$C$24,0) -> 571 | O11: =G11/D11 -> 0.14156376 | P11: R
A12: 63594 | B12: Quimbaya | C12: Quindío | D12: 31350 | E12: 1683 | F12: 5728 | G12: 12739 | H12: =G12/F12 -> 2.2239874 | I12: =E12*H12 -> 3742.9708 | J12: =ROUND(I12*Parametros!$C$25,0) -> 75 | K12: =ROUND(I12*Parametros!$C$26,0) -> 187 | L12: =ROUND(I12*Parametros!$C$24,0) -> 374 | M12: =ROUND(I12*Parametros!$C$27,0) -> 487 | N12: =ROUND(E12*Parametros!$C$28*Parametros!$C$24,0) -> 505 | O12: =G12/D12 -> 0.40634769 | P12: F
A13: 76233 | B13: Dagua | C13: Valle del Cauca | D13: 60038 | E13: 1635 | F13: 5272 | G13: 11355 | H13: =G13/F13 -> 2.1538316 | I13: =E13*H13 -> 3521.5146 | J13: =ROUND(I13*Parametros!$C$25,0) -> 70 | K13: =ROUND(I13*Parametros!$C$26,0) -> 176 | L13: =ROUND(I13*Parametros!$C$24,0) -> 352 | M13: =ROUND(I13*Parametros!$C$27,0) -> 458 | N13: =ROUND(E13*Parametros!$C$28*Parametros!$C$24,0) -> 491 | O13: =G13/D13 -> 0.18913022 | P13: P
A14: 63470 | B14: Montenegro | C14: Quindío | D14: 37483 | E14: 1048 | F14: 5423 | G14: 12407 | H14: =G14/F14 -> 2.2878481 | I14: =E14*H14 -> 2397.6648 | J14: =ROUND(I14*Parametros!$C$25,0) -> 48 | K14: =ROUND(I14*Parametros!$C$26,0) -> 120 | L14: =ROUND(I14*Parametros!$C$24,0) -> 240 | M14: =ROUND(I14*Parametros!$C$27,0) -> 312 | N14: =ROUND(E14*Parametros!$C$28*Parametros!$C$24,0) -> 314 | O14: =G14/D14 -> 0.33100339 | P14: F
A15: 76622 | B15: Roldanillo | C15: Valle del Cauca | D15: 38639 | E15: 1519 | F15: 6146 | G15: 9296 | H15: =G15/F15 -> 1.5125285 | I15: =E15*H15 -> 2297.5308 | J15: =ROUND(I15*Parametros!$C$25,0) -> 46 | K15: =ROUND(I15*Parametros!$C$26,0) -> 115 | L15: =ROUND(I15*Parametros!$C$24,0) -> 230 | M15: =ROUND(I15*Parametros!$C$27,0) -> 299 | N15: =ROUND(E15*Parametros!$C$28*Parametros!$C$24,0) -> 456 | O15: =G15/D15 -> 0.24058594 | P15: F
A16: 76890 | B16: Yotoco | C16: Valle del Cauca | D16: 16843 | E16: 651 | F16: 2522 | G16: 6237 | H16: =G16/F16 -> 2.4730373 | I16: =E16*H16 -> 1609.9473 | J16: =ROUND(I16*Parametros!$C$25,0) -> 32 | K16: =ROUND(I16*Parametros!$C$26,0) -> 80 | L16: =ROUND(I16*Parametros!$C$24,0) -> 161 | M16: =ROUND(I16*Parametros!$C$27,0) -> 209 | N16: =ROUND(E16*Parametros!$C$28*Parametros!$C$24,0) -> 195 | O16: =G16/D16 -> 0.3703022 | P16: F
... A33: 63130 | B33: Calarcá | C33: Quindío | D33: 74399 | E33: 450 | F33: 6883 | G33: 10370 | H33: =G33/F33 -> 1.5066105 | I33: =E33*H33 -> 677.97472 | J33: =ROUND(I33*Parametros!$C$25,0) -> 14 | K33: =ROUND(I33*Parametros!$C$26,0) -> 34 | L33: =ROUND(I33*Parametros!$C$24,0) -> 68 | M33: =ROUND(I33*Parametros!$C$27,0) -> 88 | N33: =ROUND(E33*Parametros!$C$28*Parametros!$C$24,0) -> 135 | O33: =G33/D33 -> 0.13938359 | P33: F
B34: TOTAL | E34: =SUM(E5:E33) -> 88091 | I34: =SUM(I5:I33) -> 188790.19 | J34: =SUM(J5:J33) -> 3777 | K34: =SUM(K5:K33) -> 9438 | L34: =SUM(L5:L33) -> 18880 | M34: =SUM(M5:M33) -> 24546 | N34: =SUM(N5:N33) -> 26428
A36: Calidad del dato: F = fuerte (RUD y reporte territorial), P = parcial, R = solo RUD. Hogar RUD = personas registradas / familias registradas (puede subestimar el tamaño real).

Sheet Coordenadas
A1: Coordenadas de cabeceras municipales (DIVIPOLA, DANE)
A4: id | B4: divipola | C4: municipio | D4: departamento | E4: tipo | F4: rol | G4: lat | H4: lon | I4: fuente_coord
A5: D66001 | B5: 66001 | C5: Pereira | D5: Risaralda | E5: demanda | F5: Afectado | G5: 4.804985 | H5: -75.719711 | I5: DIVIPOLA (DANE) datos.gov.co gdxc-w37w, consulta 30-sep-2026
A6: D76001 | B6: 76001 | C6: Cali | D6: Valle del Cauca | E6: demanda | F6: Afectado | G6: 3.413686 | H6: -76.52133 | I6: DIVIPOLA (DANE) datos.gov.co gdxc-w37w, consulta 30-sep-2026
A7: D76109 | B7: 76109 | C7: Buenaventura | D7: Valle del Cauca | E7: demanda | F7: Afectado | G7: 3.875708 | H7: -77.01074 | I7: DIVIPOLA (DANE) datos.gov.co gdxc-w37w, consulta 30-sep-2026
A8: D63001 | B8: 63001 | C8: Armenia | D8: Quindío | E8: demanda | F8: Afectado | G8: 4.53598 | H8: -75.680786 | I8: DIVIPOLA (DANE) datos.gov.co gdxc-w37w, consulta 30-sep-2026
A9: D66170 | B9: 66170 | C9: Dosquebradas | D9: Risaralda | E9: demanda | F9: Afectado | G9: 4.833131 | H9: -75.675371 | I9: DIVIPOLA (DANE) datos.gov.co gdxc-w37w, consulta 30-sep-2026
A10: D17001 | B10: 17001 | C10: Manizales | D10: Caldas | E10: demanda | F10: Afectado | G10: 5.057657 | H10: -75.491025 | I10: DIVIPOLA (DANE) datos.gov.co gdxc-w37w, consulta 30-sep-2026
A11: D66682 | B11: 66682 | C11: Santa Rosa de Cabal | D11: Risaralda | E11: demanda | F11: Afectado | G11: 4.876271 | H11: -75.623268 | I11: DIVIPOLA (DANE) datos.gov.co gdxc-w37w, consulta 30-sep-2026
A12: D63594 | B12: 63594 | C12: Quimbaya | D12: Quindío | E12: demanda | F12: Afectado | G12: 4.624387 | H12: -75.765074 | I12: DIVIPOLA (DANE) datos.gov.co gdxc-w37w, consulta 30-sep-2026
A13: D76233 | B13: 76233 | C13: Dagua | D13: Valle del Cauca | E13: demanda | F13: Afectado | G13: 3.657318 | H13: -76.68886 | I13: DIVIPOLA (DANE) datos.gov.co gdxc-w37w, consulta 30-sep-2026
A14: D63470 | B14: 63470 | C14: Montenegro | D14: Quindío | E14: demanda | F14: Afectado | G14: 4.565057 | H14: -75.749827 | I14: DIVIPOLA (DANE) datos.gov.co gdxc-w37w, consulta 30-sep-2026
A15: D76622 | B15: 76622 | C15: Roldanillo | D15: Valle del Cauca | E15: demanda | F15: Afectado | G15: 4.413601 | H15: -76.152277 | I15: DIVIPOLA (DANE) datos.gov.co gdxc-w37w, consulta 30-sep-2026
A16: D76890 | B16: 76890 | C16: Yotoco | D16: Valle del Cauca | E16: demanda | F16: Afectado | G16: 3.861241 | H16: -76.382698 | I16: DIVIPOLA (DANE) datos.gov.co gdxc-w37w, consulta 30-sep-2026
... A51: R01 | B51: 63401 | C51: La Tebaida | D51: Quindío | E51: candidato | F51: Reserva | G51: 4.453755 | H51: -75.786887 | I51: DIVIPOLA (DANE) datos.gov.co gdxc-w37w, consulta 30-sep-2026

Sheet Distancias_km
A1: Distancias por carretera d_ij (km) — MATRIZ FINAL usada por el modelo
A2: Celdas amarillas: valor de Google Maps (1-oct-2026). Resto: OSRM/OpenStreetMap (30-sep-2026). Costo de transporte = 500 COP × km × persona.
A4: id_demanda | B4: municipio | C4: C01 Palmira | D4: C02 Tuluá | E4: C03 Jamundí | F4: C04 Cartago | G4: C05 Guadalajara de Buga | H4: C06 Candelaria | I4: C07 Yumbo | J4: C08 Florida | K4: C09 El Cerrito | L4: C10 Pradera | M4: C11 Guacarí | N4: C12 Ginebra | O4: C13 Chinchiná | P4: C14 Supía | Q4: C15 Aguadas | R4: C16 Pensilvania | S4: C17 La Dorada | T4: R01 La Tebaida
A5: D66001 | B5: Pereira | C5: 195 | D5: 117 | E5: 230 | F5: 30.4 | G5: 141.9 | H5: 203 | I5: 200 | J5: 222 | K5: 170 | L5: 206 | M5: 159.4 | N5: 172 | O5: 33 | P5: 107.2 | Q5: 178 | R5: 192 | S5: 223 | T5: 67.1
A6: D76001 | B6: Cali | C6: 34.4 | D6: 96.5 | E6: 19.6 | F6: 185 | G6: 74.5 | H6: 27.7 | I6: 17.7 | J6: 41.8 | K6: 50.3 | L6: 41.4 | M6: 59 | N6: 55.9 | O6: 245.1 | P6: 301.2 | Q6: 366.1 | R6: 402.9 | S6: 432.6 | T6: 169
A7: D76109 | B7: Buenaventura | C7: 144 | D7: 135.1 | E7: 137.6 | F7: 225 | G7: 111 | H7: 140.8 | I7: 128.4 | J7: 154.9 | K7: 133.6 | L7: 155 | M7: 124.6 | N7: 136.3 | O7: 279.3 | P7: 335.3 | Q7: 400.3 | R7: 437 | S7: 466.8 | T7: 208
A8: D63001 | B8: Armenia | C8: 167 | D8: 89.1 | E8: 202 | F8: 53.4 | G8: 118.2 | H8: 174 | I8: 171 | J8: 193 | K8: 144.6 | L8: 178 | M8: 135.6 | N8: 147.3 | O8: 76.7 | P8: 151.4 | Q8: 220 | R8: 289.1 | S8: 244 | T8: 20.1
A9: D66170 | B9: Dosquebradas | C9: 199 | D9: 120.8 | E9: 233.1 | F9: 34 | G9: 145.6 | H9: 207 | I9: 203 | J9: 226 | K9: 174 | L9: 210 | M9: 164 | N9: 175 | O9: 26.1 | P9: 100.7 | Q9: 171 | R9: 185 | S9: 216 | T9: 68.8
A10: D17001 | B10: Manizales | C10: 242 | D10: 171 | E10: 282.8 | F10: 83.7 | G10: 196 | H10: 255.5 | I10: 252.1 | J10: 273.6 | K10: 223 | L10: 259.7 | M10: 212 | N10: 224 | O10: 27.6 | P10: 82 | Q10: 122.6 | R10: 135 | S10: 166 | T10: 118.9
A11: D66682 | B11: Santa Rosa de Cabal | C11: 210 | D11: 131.2 | E11: 243.5 | F11: 44.4 | G11: 156 | H11: 218 | I11: 215 | J11: 234.3 | K11: 185 | L11: 222 | M11: 175 | N11: 187 | O11: 14.7 | P11: 89.4 | Q11: 156.1 | R11: 173 | S11: 204 | T11: 79.6
A12: D63594 | B12: Quimbaya | C12: 194 | D12: 116 | E12: 229 | F12: 32 | G12: 140.7 | H12: 202 | I12: 199 | J12: 221 | K12: 169 | L12: 205 | M12: 158.1 | N12: 170 | O12: 65.9 | P12: 144 | Q12: 218 | R12: 242 | S12: 263.4 | T12: 28.4
A13: D76233 | B13: Dagua | C13: 75 | D13: 94.8 | E13: 70.3 | F13: 184 | G13: 69.7 | H13: 73.5 | I13: 61.1 | J13: 87.6 | K13: 93.3 | L13: 92.7 | M13: 84.2 | N13: 96 | O13: 238.9 | P13: 295 | Q13: 360 | R13: 396.7 | S13: 426.4 | T13: 167
A14: D63470 | B14: Montenegro | C14: 168 | D14: 90.8 | E14: 203 | F14: 41.8 | G14: 115.5 | H14: 176 | I14: 173 | J14: 195 | K14: 142 | L14: 180 | M14: 132.9 | N14: 144.7 | O14: 75.7 | P14: 153.9 | Q14: 224 | R14: 299.6 | S14: 254 | T14: 19.5
A15: D76622 | B15: Roldanillo | C15: 118.7 | D15: 47.3 | E15: 159.5 | F15: 58.7 | G15: 72 | H15: 132.2 | I15: 123 | J15: 150.4 | K15: 98.5 | L15: 136.4 | M15: 89.5 | N15: 101.2 | O15: 114.4 | P15: 162 | Q15: 240 | R15: 272.2 | S15: 316.2 | T15: 56.3
A16: D76890 | B16: Yotoco | C16: 56.6 | D16: 37.9 | E16: 77.4 | F16: 126.3 | G16: 12.8 | H16: 70.2 | I16: 44.3 | J16: 88.3 | K16: 36.4 | L16: 74.4 | M16: 27.4 | N16: 39.1 | O16: 185 | P16: 239 | Q16: 303.1 | R16: 339.8 | S16: 369.6 | T16: 109.7
... A33: D63130 | B33: Calarcá | C33: 173 | D33: 97.2 | E33: 208 | F33: 59.5 | G33: 121.9 | H33: 181 | I33: 178 | J33: 200 | K33: 148.4 | L33: 184 | M33: 139.3 | N33: 151 | O33: 74.7 | P33: 149.4 | Q33: 220 | R33: 283.5 | S33: 238 | T33: 23.9

Sheet Distancias_OSRM
A1: Distancias OSRM originales (km) — solo referencia; el modelo usa la hoja Distancias_km
A4: id_demanda | B4: municipio | C4: C01 Palmira | D4: C02 Tuluá | E4: C03 Jamundí | F4: C04 Cartago | G4: C05 Guadalajara de Buga | H4: C06 Candelaria | I4: C07 Yumbo | J4: C08 Florida | K4: C09 El Cerrito | L4: C10 Pradera | M4: C11 Guacarí | N4: C12 Ginebra | O4: C13 Chinchiná | P4: C14 Supía | Q4: C15 Aguadas | R4: C16 Pensilvania | S4: C17 La Dorada | T4: R01 La Tebaida
A5: D66001 | B5: Pereira | C5: 188.6 | D5: 117.2 | E5: 229.4 | F5: 30.3 | G5: 141.9 | H5: 202.1 | I5: 198.7 | J5: 220.3 | K5: 168.4 | L5: 206.3 | M5: 159.4 | N5: 171.1 | O5: 32.6 | P5: 107.2 | Q5: 174 | R5: 190.3 | S5: 269.9 | T5: 67.1
A6: D76001 | B6: Cali | C6: 33.1 | D6: 100.9 | E6: 19.5 | F6: 189.3 | G6: 74.5 | H6: 27.7 | I6: 17.7 | J6: 41.8 | K6: 50.3 | L6: 41.4 | M6: 59 | N6: 55.9 | O6: 245.1 | P6: 301.2 | Q6: 366.1 | R6: 402.9 | S6: 432.6 | T6: 172.7
A7: D76109 | B7: Buenaventura | C7: 153.8 | D7: 135.1 | E7: 137.6 | F7: 223.5 | G7: 110 | H7: 140.8 | I7: 128.4 | J7: 154.9 | K7: 133.6 | L7: 171.6 | M7: 124.6 | N7: 136.3 | O7: 279.3 | P7: 335.3 | Q7: 400.3 | R7: 437 | S7: 466.8 | T7: 206.9
A8: D63001 | B8: Armenia | C8: 164.9 | D8: 93.4 | E8: 205.7 | F8: 53.2 | G8: 118.2 | H8: 178.4 | I8: 175 | J8: 196.5 | K8: 144.6 | L8: 182.6 | M8: 135.6 | N8: 147.3 | O8: 76.7 | P8: 151.4 | Q8: 218.1 | R8: 289.1 | S8: 243.3 | T8: 20.1
A9: D66170 | B9: Dosquebradas | C9: 192.3 | D9: 120.8 | E9: 233.1 | F9: 34 | G9: 145.6 | H9: 205.8 | I9: 202.4 | J9: 223.9 | K9: 172 | L9: 210 | M9: 163 | N9: 174.7 | O9: 26.1 | P9: 100.7 | Q9: 167.5 | R9: 183.9 | S9: 263.4 | T9: 68.8
A10: D17001 | B10: Manizales | C10: 242 | D10: 170.6 | E10: 282.8 | F10: 83.7 | G10: 195.3 | H10: 255.5 | I10: 252.1 | J10: 273.6 | K10: 221.8 | L10: 259.7 | M10: 212.7 | N10: 224.5 | O10: 27.5 | P10: 82 | Q10: 122.6 | R10: 134.2 | S10: 213.8 | T10: 118.9
A11: D66682 | B11: Santa Rosa de Cabal | C11: 202.7 | D11: 131.2 | E11: 243.5 | F11: 44.4 | G11: 156 | H11: 216.2 | I11: 212.8 | J11: 234.3 | K11: 182.4 | L11: 220.4 | M11: 173.4 | N11: 185.1 | O11: 14.7 | P11: 89.4 | Q11: 156.1 | R11: 172.5 | S11: 252.1 | T11: 79.6
A12: D63594 | B12: Quimbaya | C12: 187.4 | D12: 116 | E12: 228.2 | F12: 32 | G12: 140.7 | H12: 200.9 | I12: 197.5 | J12: 219 | K12: 167.2 | L12: 205.1 | M12: 158.1 | N12: 169.8 | O12: 65.9 | P12: 144 | Q12: 209 | R12: 223.7 | S12: 263.4 | T12: 28.4
A13: D76233 | B13: Dagua | C13: 75 | D13: 94.8 | E13: 70.3 | F13: 183.1 | G13: 69.7 | H13: 73.5 | I13: 61.1 | J13: 87.6 | K13: 93.3 | L13: 92.7 | M13: 84.2 | N13: 96 | O13: 238.9 | P13: 295 | Q13: 360 | R13: 396.7 | S13: 426.4 | T13: 166.5
A14: D63470 | B14: Montenegro | C14: 162.2 | D14: 90.8 | E14: 203 | F14: 41.8 | G14: 115.5 | H14: 175.7 | I14: 172.3 | J14: 193.8 | K14: 142 | L14: 179.9 | M14: 132.9 | N14: 144.7 | O14: 75.7 | P14: 153.9 | Q14: 218.8 | R14: 299.6 | S14: 253.7 | T14: 19.5
A15: D76622 | B15: Roldanillo | C15: 118.7 | D15: 47.3 | E15: 159.5 | F15: 58.7 | G15: 72 | H15: 132.2 | I15: 123 | J15: 150.4 | K15: 98.5 | L15: 136.4 | M15: 89.5 | N15: 101.2 | O15: 114.4 | P15: 170.5 | Q15: 235.5 | R15: 272.2 | S15: 316.2 | T15: 56.3
A16: D76890 | B16: Yotoco | C16: 56.6 | D16: 37.9 | E16: 77.4 | F16: 126.3 | G16: 12.8 | H16: 70.2 | I16: 44.3 | J16: 88.3 | K16: 36.4 | L16: 74.4 | M16: 27.4 | N16: 39.1 | O16: 182 | P16: 238.1 | Q16: 303.1 | R16: 339.8 | S16: 369.6 | T16: 109.7
... A33: D63130 | B33: Calarcá | C33: 168.6 | D33: 97.2 | E33: 209.4 | F33: 59.5 | G33: 121.9 | H33: 182.1 | I33: 178.7 | J33: 200.2 | K33: 148.4 | L33: 186.3 | M33: 139.3 | N33: 151 | O33: 74.7 | P33: 149.4 | Q33: 216.2 | R33: 283.5 | S33: 237.6 | T33: 23.9

Sheet Alcance_180km
A1: Alcance de cada sitio a ≤ 180 km
A4: id | B4: municipio | C4: rol | D4: demandas_a_180km | E4: demanda_base_a_180km | F4: dist_min_km | G4: municipios_a_180km | H4: pares_que_dependen_de_Google | I4: cumple_criterio_ciudad_cercana | J4: criterio_ciudad_cercana
A5: C01 | B5: Palmira | C5: Candidato | D5: 20 | E5: 10347 | F5: 34.4 | G5: Cali, Buenaventura, Armenia, Dagua, Montenegro, Roldanillo, Yotoco, Trujillo, La Unión, Toro, Restrepo, Zarzal, Sevilla, Ansermanuevo, La Cumbre, Bugalagrande, Riofrío, Caicedonia, Circasia, Calarcá | H5: 0 | I5: Sí | J5: ≥ 1 municipio afectado a ≤ 180 km por carretera (matriz final)
A6: C02 | B6: Tuluá | C6: Candidato | D6: 29 | E6: 18880 | F6: 14.3 | G6: Pereira, Cali, Buenaventura, Armenia, Dosquebradas, Manizales, Santa Rosa de Cabal, Quimbaya, Dagua, Montenegro, Roldanillo, Yotoco, Trujillo, Argelia, Villamaría, La Unión, Toro, Restrepo, Zarzal, Sevilla, El Cairo, Ansermanuevo, La Cumbre, La Virginia, Bugalagrande, Riofrío, Caicedonia, Circasia, Calarcá | H6: 0 | I6: Sí | J6: ≥ 1 municipio afectado a ≤ 180 km por carretera (matriz final)
A7: C03 | B7: Jamundí | C7: Candidato | D7: 13 | E7: 8294 | F7: 19.6 | G7: Cali, Buenaventura, Dagua, Roldanillo, Yotoco, Trujillo, La Unión, Restrepo, Zarzal, Sevilla, La Cumbre, Bugalagrande, Riofrío | H7: 0 | I7: Sí | J7: ≥ 1 municipio afectado a ≤ 180 km por carretera (matriz final)
A8: C04 | B8: Cartago | C8: Candidato | D8: 25 | E8: 11798 | F8: 11.5 | G8: Pereira, Armenia, Dosquebradas, Manizales, Santa Rosa de Cabal, Quimbaya, Montenegro, Roldanillo, Yotoco, Trujillo, Argelia, Villamaría, La Unión, Toro, Restrepo, Zarzal, Sevilla, El Cairo, Ansermanuevo, La Virginia, Bugalagrande, Riofrío, Caicedonia, Circasia, Calarcá | H8: 0 | I8: Sí | J8: ≥ 1 municipio afectado a ≤ 180 km por carretera (matriz final)
A9: C05 | B9: Guadalajara de Buga | C9: Candidato | D9: 26 | E9: 17917 | F9: 12.8 | G9: Pereira, Cali, Buenaventura, Armenia, Dosquebradas, Santa Rosa de Cabal, Quimbaya, Dagua, Montenegro, Roldanillo, Yotoco, Trujillo, Argelia, La Unión, Toro, Restrepo, Zarzal, Sevilla, Ansermanuevo, La Cumbre, La Virginia, Bugalagrande, Riofrío, Caicedonia, Circasia, Calarcá | H9: 0 | I9: Sí | J9: ≥ 1 municipio afectado a ≤ 180 km por carretera (matriz final)
A10: C06 | B10: Candelaria | C10: Candidato | D10: 17 | E10: 10107 | F10: 27.7 | G10: Cali, Buenaventura, Armenia, Dagua, Montenegro, Roldanillo, Yotoco, Trujillo, La Unión, Toro, Restrepo, Zarzal, Sevilla, La Cumbre, Bugalagrande, Riofrío, Caicedonia | H10: 0 | I10: Sí | J10: ≥ 1 municipio afectado a ≤ 180 km por carretera (matriz final)
A11: C07 | B11: Yumbo | C11: Candidato | D11: 18 | E11: 10175 | F11: 17.7 | G11: Cali, Buenaventura, Armenia, Dagua, Montenegro, Roldanillo, Yotoco, Trujillo, La Unión, Toro, Restrepo, Zarzal, Sevilla, La Cumbre, Bugalagrande, Riofrío, Caicedonia, Calarcá | H11: 0 | I11: Sí | J11: ≥ 1 municipio afectado a ≤ 180 km por carretera (matriz final)
A12: C08 | B12: Florida | C12: Candidato | D12: 15 | E12: 8502 | F12: 41.8 | G12: Cali, Buenaventura, Dagua, Roldanillo, Yotoco, Trujillo, La Unión, Toro, Restrepo, Zarzal, Sevilla, La Cumbre, Bugalagrande, Riofrío, Caicedonia | H12: 0 | I12: Sí | J12: ≥ 1 municipio afectado a ≤ 180 km por carretera (matriz final)
A13: C09 | B13: El Cerrito | C13: Candidato | D13: 25 | E13: 17481 | F13: 36.4 | G13: Pereira, Cali, Buenaventura, Armenia, Dosquebradas, Quimbaya, Dagua, Montenegro, Roldanillo, Yotoco, Trujillo, Argelia, La Unión, Toro, Restrepo, Zarzal, Sevilla, Ansermanuevo, La Cumbre, La Virginia, Bugalagrande, Riofrío, Caicedonia, Circasia, Calarcá | H13: 0 | I13: Sí | J13: ≥ 1 municipio afectado a ≤ 180 km por carretera (matriz final)
A14: C10 | B14: Pradera | C14: Candidato | D14: 17 | E14: 10107 | F14: 41.4 | G14: Cali, Buenaventura, Armenia, Dagua, Montenegro, Roldanillo, Yotoco, Trujillo, La Unión, Toro, Restrepo, Zarzal, Sevilla, La Cumbre, Bugalagrande, Riofrío, Caicedonia | H14: 1 | I14: Sí | J14: ≥ 1 municipio afectado a ≤ 180 km por carretera (matriz final)
A15: C11 | B15: Guacarí | C15: Candidato | D15: 26 | E15: 17917 | F15: 27.4 | G15: Pereira, Cali, Buenaventura, Armenia, Dosquebradas, Santa Rosa de Cabal, Quimbaya, Dagua, Montenegro, Roldanillo, Yotoco, Trujillo, Argelia, La Unión, Toro, Restrepo, Zarzal, Sevilla, Ansermanuevo, La Cumbre, La Virginia, Bugalagrande, Riofrío, Caicedonia, Circasia, Calarcá | H15: 0 | I15: Sí | J15: ≥ 1 municipio afectado a ≤ 180 km por carretera (matriz final)
A16: C12 | B16: Ginebra | C16: Candidato | D16: 24 | E16: 17335 | F16: 39.1 | G16: Pereira, Cali, Buenaventura, Armenia, Dosquebradas, Quimbaya, Dagua, Montenegro, Roldanillo, Yotoco, Trujillo, La Unión, Toro, Restrepo, Zarzal, Sevilla, Ansermanuevo, La Cumbre, La Virginia, Bugalagrande, Riofrío, Caicedonia, Circasia, Calarcá | H16: 0 | I16: Sí | J16: ≥ 1 municipio afectado a ≤ 180 km por carretera (matriz final)
... A22: R01 | B22: La Tebaida | C22: Reserva | D22: 28 | E22: 16839 | F22: 19.5 | G22: Pereira, Cali, Armenia, Dosquebradas, Manizales, Santa Rosa de Cabal, Quimbaya, Dagua, Montenegro, Roldanillo, Yotoco, Trujillo, Argelia, Villamaría, La Unión, Toro, Restrepo, Zarzal, Sevilla, El Cairo, Ansermanuevo, La Cumbre, La Virginia, Bugalagrande, Riofrío, Caicedonia, Circasia, Calarcá | H22: 0 | I22: Sí | J22: ≥ 1 municipio afectado a ≤ 180 km por carretera (matriz final)

Sheet Control_distancias
A1: Verificación OSRM vs. Google Maps — COMPLETADA (164 pares, 1-oct-2026)
A2: Google Maps, modo carro, primera ruta sugerida. En la matriz final manda Google Maps en estos pares. Filas rojas: cambian la factibilidad a 180 km.
A4: id_demanda | B4: id_sitio | C4: municipio_origen | D4: sitio_destino | E4: grupo | F4: km_OSRM | G4: km_Google_Maps | H4: km_linea_recta | I4: diferencia_km | J4: diferencia_pct | K4: factible_OSRM | L4: factible_Google | M4: cambia_factibilidad | N4: revisar_>10% | O4: fecha_consulta | P4: url_consulta
A5: D66001 | B5: C04 | C5: Pereira | D5: Cartago | E5: control | F5: 30.343 | G5: 30.4 | H5: 23.7 | I5: 0.1 | J5: 0.2 | K5: 1 | L5: 1 | M5: 0 | N5: 0 | O5: 2026-10-01 | P5: https://www.google.com/maps/dir/4.804985,-75.719711/4.742192,-75.924374/data=!4m2!4m1!3e0?hl=es
A6: D66001 | B6: C13 | C6: Pereira | D6: Chinchiná | E6: control | F6: 32.555 | G6: 33 | H6: 23.6 | I6: 0.4 | J6: 1.4 | K6: 1 | L6: 1 | M6: 0 | N6: 0 | O6: 2026-10-01 | P6: https://www.google.com/maps/dir/4.804985,-75.719711/4.985227,-75.607529/data=!4m2!4m1!3e0?hl=es
A7: D63001 | B7: C04 | C7: Armenia | D7: Cartago | E7: control | F7: 53.196 | G7: 53.4 | H7: 35.4 | I7: 0.2 | J7: 0.4 | K7: 1 | L7: 1 | M7: 0 | N7: 0 | O7: 2026-10-01 | P7: https://www.google.com/maps/dir/4.535980,-75.680786/4.742192,-75.924374/data=!4m2!4m1!3e0?hl=es
A8: D17001 | B8: C13 | C8: Manizales | D8: Chinchiná | E8: control | F8: 27.502 | G8: 27.6 | H8: 15.2 | I8: 0.1 | J8: 0.4 | K8: 1 | L8: 1 | M8: 0 | N8: 0 | O8: 2026-10-01 | P8: https://www.google.com/maps/dir/5.057657,-75.491025/4.985227,-75.607529/data=!4m2!4m1!3e0?hl=es
A9: D76001 | B9: C01 | C9: Cali | D9: Palmira | E9: control | F9: 33.065 | G9: 34.4 | H9: 28 | I9: 1.3 | J9: 4 | K9: 1 | L9: 1 | M9: 0 | N9: 0 | O9: 2026-10-01 | P9: https://www.google.com/maps/dir/3.413686,-76.521330/3.531544,-76.298846/data=!4m2!4m1!3e0?hl=es
A10: D76001 | B10: C03 | C10: Cali | D10: Jamundí | E10: control | F10: 19.459 | G10: 19.6 | H10: 17.3 | I10: 0.1 | J10: 0.7 | K10: 1 | L10: 1 | M10: 0 | N10: 0 | O10: 2026-10-01 | P10: https://www.google.com/maps/dir/3.413686,-76.521330/3.258751,-76.538472/data=!4m2!4m1!3e0?hl=es
A11: D76109 | B11: C05 | C11: Buenaventura | D11: Guadalajara de Buga | E11: control | F11: 110.009 | G11: 111 | H11: 79 | I11: 1 | J11: 0.9 | K11: 1 | L11: 1 | M11: 0 | N11: 0 | O11: 2026-10-01 | P11: https://www.google.com/maps/dir/3.875708,-77.010740/3.900736,-76.298979/data=!4m2!4m1!3e0?hl=es
A12: D66001 | B12: C02 | C12: Pereira | D12: Tuluá | E12: control | F12: 117.184 | G12: 117 | H12: 96 | I12: -0.2 | J12: -0.2 | K12: 1 | L12: 1 | M12: 0 | N12: 0 | O12: 2026-10-01 | P12: https://www.google.com/maps/dir/4.804985,-75.719711/4.085399,-76.197731/data=!4m2!4m1!3e0?hl=es
A13: D66001 | B13: C17 | C13: Pereira | D13: La Dorada | E13: control | F13: 269.932 | G13: 223 | H13: 137.3 | I13: -46.9 | J13: -17.4 | K13: 0 | L13: 0 | M13: 0 | N13: 1 | O13: 2026-10-01 | P13: https://www.google.com/maps/dir/4.804985,-75.719711/5.460834,-74.668819/data=!4m2!4m1!3e0?hl=es
A14: D66170 | B14: C17 | C14: Dosquebradas | D14: La Dorada | E14: control | F14: 263.443 | G14: 216 | H14: 131.5 | I14: -47.4 | J14: -18 | K14: 0 | L14: 0 | M14: 0 | N14: 1 | O14: 2026-10-01 | P14: https://www.google.com/maps/dir/4.833131,-75.675371/5.460834,-74.668819/data=!4m2!4m1!3e0?hl=es
A15: D66682 | B15: C17 | C15: Santa Rosa de Cabal | D15: La Dorada | E15: control | F15: 252.077 | G15: 204 | H15: 124.1 | I15: -48.1 | J15: -19.1 | K15: 0 | L15: 0 | M15: 0 | N15: 1 | O15: 2026-10-01 | P15: https://www.google.com/maps/dir/4.876271,-75.623268/5.460834,-74.668819/data=!4m2!4m1!3e0?hl=es
A16: D17001 | B16: C16 | C16: Manizales | D16: Pensilvania | E16: control | F16: 134.173 | G16: 135 | H16: 51.5 | I16: 0.8 | J16: 0.6 | K16: 1 | L16: 1 | M16: 0 | N16: 0 | O16: 2026-10-01 | P16: https://www.google.com/maps/dir/5.057657,-75.491025/5.383281,-75.160299/data=!4m2!4m1!3e0?hl=es
... A168: D76113 | B168: C15 | C168: Bugalagrande | D168: Aguadas | E168: ruta_montaña_>230km | F168: 249.962 | G168: 263 | H168: 174.2 | I168: 13 | J168: 5.2 | K168: 0 | L168: 0 | M168: 0 | N168: 0 | O168: 2026-10-01 | P168: https://www.google.com/maps/dir/4.208358,-76.156820/5.610244,-75.454870/data=!4m2!4m1!3e0?hl=es

Sheet Fuentes
A1: Fuentes de datos (IDs ordenados; estado de verificación al 5-oct-2026)
A2: Una fuente que no se pudo abrir se marca 'No verificada'. Referencias completas en docs/bibliografia.md.
A4: ID | B4: Fuente | C4: URL | D4: Tipo | E4: Uso en el proyecto | F4: Verificación
A5: F01 | B5: UNGRD — Registro Único de Damnificados (RUD) del terremoto del 10-ago-2026, consolidado por municipio, corte 17-sep-2026, consultado a través del agregador secundario datosdelterremoto.org | C5: https://datosdelterremoto.org | D5: Dato oficial vía agregador secundario | E5: NH, familias y personas registradas (demanda d_i y filtros S1, S2, S7) | F5: No verificada en esta revisión: el acceso al sitio no se pudo confirmar el 5-oct-2026; los valores vienen del libro original del grupo
A6: F02 | B6: DANE (2025). Proyecciones de población municipal por área 2018-2042 (PPED), actualizado el 30-jul-2025 (archivo PPED-AreaMun-2018-2042_VP.xlsx en data/raw/dane) | C6: https://www.dane.gov.co/index.php/estadisticas-por-tema/demografia-y-poblacion/proyecciones-de-poblacion | D6: Dato oficial | E6: Población 2026 de los 47 municipios (47/47 coinciden con el archivo) y categoría de los candidatos | F6: Verificada (5-oct-2026): la página del DANE publica la serie municipal por área 2018-2042 (publicación 8-ago-2025); el archivo dice 'Actualizado el 30 de julio de 2025'
A7: F03 | B7: DANE. Proyecciones municipales de población 2020-2035, actualización post-COVID-19 (DCD) (archivo DCD-area-proypoblacion-Mun-2020-2035-ActPostCOVID-19.xlsx en data/raw/dane) | C7: https://www.dane.gov.co/index.php/estadisticas-por-tema/demografia-y-poblacion/proyecciones-de-poblacion | D7: Dato oficial | E7: Solo control: sensibilidad de la categoría de los candidatos a la fuente de población | F7: Parcial: el archivo está en data/raw/dane, pero en la página consultada el 5-oct-2026 no se identificó un enlace con ese nombre
A8: F04 | B8: DANE. DIVIPOLA — Códigos de municipios geolocalizados (corte 30-dic-2024), portal datos.gov.co, recurso gdxc-w37w (consulta 30-sep-2026) | C8: https://www.datos.gov.co/Mapas-Nacionales/DIVIPOLA-C-digos-municipios-geolocalizados/gdxc-w37w | D8: Dato oficial | E8: Coordenadas de la cabecera de los 47 municipios | F8: Verificada (5-oct-2026): metadatos del recurso (atribución DANE, corte 30-dic-2024); respuesta original en data/raw
A9: F05 | B9: OpenStreetMap + Project OSRM, servicio table v1, perfil driving (consulta 30-sep-2026) | C9: https://router.project-osrm.org/table/v1/driving/ | D9: Servicio de ruteo (datos abiertos) | E9: Distancias por carretera de los pares no verificados en Google Maps | F9: Verificada: 58 respuestas originales guardadas con su URL en data/raw/osrm; 5 llamadas re-consultadas coincidieron
A10: F06 | B10: El Tiempo, blog 'Venga le cuento' (14-ago-2026). Kits de ayuda a damnificados por el terremoto desde $14.650 | C10: https://blogs.eltiempo.com/venga-le-cuento/2026/08/14/kits-de-ayuda-a-damnificados-por-el-terremoto-desde-14-650/ | D10: Prensa | E10: Costo de un kit de alimentación (29.730) y uno de aseo (29.730); v = 60.000 COP (redondeo) | F10: No verificada: el sitio responde 403 al acceso automatizado (5-oct-2026); título y fecha identificados en el buscador; los precios vienen del libro del grupo. Corroboración parcial en F17
A11: F07 | B11: El Cronista (02-sep-2026). La Ungrd entregará hasta $3,1 millones a familias afectadas por el terremoto | C11: https://www.cronista.com/colombia/actualidad-co/la-ungrd-entregara-hasta-31-millones-a-familias-afectadas-por-el-terremoto-quienes-pueden-cobrarlo/ | D11: Prensa | E11: Referencia del costo fijo por plaza c_f (supuesto provisional) y de T = 3 meses | F11: Verificada (5-oct-2026): 3 meses; $787.907,25 a $1.050.543 por hogar-mes según categoría del municipio
A12: F08 | B12: Universidad de La Sabana. Caso 2. Terremoto en Colombia (enunciado, Prof. Gonzalo Mejía) | C12: docs/Caso_2_Terremoto_en_Colombia_enunciado.pdf (archivo local) | D12: Enunciado | E12: Capacidades 3.000/1.000/500, tarifa 500 COP/km·persona, 180 km, regla del presupuesto | F12: Verificada (archivo del curso)
A13: F09 | B13: Google Maps, indicaciones en carro, primera ruta sugerida (consultas 1-oct-2026 y 5-oct-2026) | C13: https://www.google.com/maps (URL de cada consulta en data/raw/google_maps y en las hojas Control_distancias y Control_140_160km) | D13: Servicio de ruteo | E13: Distancias de 164 pares de la matriz final (1-oct) y control de 48 pares de 140–160 km (5-oct) | F13: Verificada: cada par tiene su URL; Google muestra km enteros desde 100 km
A14: F10 | B14: Association of Bay Area Governments — ABAG (2017). Bay Area Earthquake Shelter Needs (white paper; estimaciones con la metodología Hazus de FEMA) | C14: https://files.mtc.ca.gov/library/pub/ABAG/30232.pdf | D14: Informe técnico | E14: Sustenta f = 10 % como escenario de planeación y la sensibilidad 8,3 / 11,6 / 13 % | F14: Verificada (5-oct-2026): 11,6 % de los desplazados busca refugio en el escenario Hayward; 8,3 % (Napa) a 13,2 % (Solano) por condado; demografía de EE. UU.
A15: F11 | B15: OPS/OMS (10-ago-2026). Informe de situación 2: Colombia — Terremoto agosto 2026 | C15: https://www.paho.org/es/documentos/informe-situacion-2-colombia-terremoto-agosto-2026-10-agosto-2026 | D15: Informe de situación | E15: Contexto del evento | F15: Verificada (5-oct-2026): magnitud 7,4; profundidad 103 km; sentido en 16 departamentos y afectaciones en 12
... A22: F18 | B22: UNGRD (2024). Protocolo de alojamientos temporales (Estrategia Nacional de Respuesta) | C22: https://portal.gestiondelriesgo.gov.co/Documents/ENRE/5-Alojamientos-temporales.pdf | D22: Documento técnico oficial | E22: Búsqueda de una referencia pública para c_f: el protocolo no publica costos; sí el estándar de 3,5 m² por persona | F22: Verificada (5-oct-2026): sin cifras de costo

Sheet Registro_cambios
A1: Registro de correcciones y complementos (30-sep, 1-oct y 5-oct-2026)
A4: Elemento | B4: Antes | C4: Ahora | D4: Motivo
A5: Coordenadas | B5: Pendientes (notebook 01 sin ejecutar) | C5: DIVIPOLA oficial para los 47 nodos | D5: Requisito del caso; un punto (cabecera municipal) por municipio
A6: Distancias | B6: No existían (sensibilidad preliminar usaba distancias no documentadas) | C6: Matriz 29×18 por carretera (OSRM + Google Maps en 164 pares) | D6: Requisito del caso; cifras preliminares quedan reemplazadas
A7: Distancias (verificación) | B7: Pares de control 'PENDIENTE' de cotejar con Google Maps | C7: 164 pares verificados en Google Maps; manda Google Maps en ellos | D7: Mediana Google/OSRM ≈ 1,005; 7 pares cambian de factibilidad a 180 km
A8: La Dorada (C17) | B8: Marcada sin ningún municipio a ≤ 180 km (OSRM 212,9 km) | C8: Alcanza a Manizales (166 km) y Villamaría (165 km) según Google Maps | D8: Error de ruteo OSRM (rodeo por el sur); 17 candidatos útiles
A9: Sensibilidad c_f | B9: Tabla 'techo' preliminar | C9: Recalculada con el MILP y distancias reales (notebook 02) | D9: La tabla preliminar no es reproducible
A10: Costo variable | B10: 60.000 COP | C10: Kit de alimentación 29.730 + kit de aseo 29.730 = 59.460; v = 60.000 se declara como redondeo (+540) | D10: Transparencia (5-oct-2026: parámetros separados)
A11: Fuentes | B11: Hoja con 9 fuentes sin URL ni estado | C11: 18 fuentes con URL, tipo, uso y verificación; IDs ordenados | D11: Revisión 5-oct-2026
A12: Albergados observados | B12: Rango observado citado sin tabla ni fuente | C12: Tabla con fuente: 0,4 % (Cali) a 4,4 % (Dosquebradas) de las personas en NH | D12: Revisión 5-oct-2026
A13: Distancias 140–160 km | B13: 48 pares OSRM sin verificar | C13: Verificados en Google Maps (5-oct-2026); ninguno cambia de factibilidad | D13: Revisión 5-oct-2026; se usan como sensibilidad
A14: Criterio 'ciudad cercana' | B14: Implícito | C14: ≥ 1 municipio afectado a ≤ 180 km por carretera, reportado por candidato | D14: Revisión 5-oct-2026

Sheet Albergados_observados
A1: Tasa de albergue observada = albergados ÷ personas en viviendas no habitables (NH × hogar RUD)
A2: Fechas no comparables (18-ago puntual vs. promedio de 48 días). f = 10 % es un escenario de planeación, no una tasa observada.
A4: municipio | B4: departamento | C4: albergados | D4: fecha_dato | E4: dias_desde_sismo | F4: tipo_dato | G4: personas_en_NH | H4: veces_f_base | I4: fuente_id | J4: fuente | K4: url | L4: verificacion | M4: nota | N4: tasa_observada_pct
A5: Pereira | B5: Risaralda | C5: 1300 | D5: 2026-08-18 | E5: 8 | F5: personas en albergues en la fecha | G5: 56069 | H5: 4.313 | I5: F14 | J5: El Nuevo Siglo, 18-ago-2026 | K5: https://www.elnuevosiglo.com.co/nacion/2013-personas-permanecen-en-albergues-tras-terremoto-en-colombia | L5: Verificada (consulta 5-oct-2026) | M5: 7 albergues; el artículo reporta 2.013 personas en 14 albergues del país | N5: 2.32
A6: Manizales | B6: Caldas | C6: 195 | D6: 2026-08-18 | E6: 8 | F6: personas en albergues en la fecha | G6: 7223 | H6: 3.7041026 | I6: F14 | J6: El Nuevo Siglo, 18-ago-2026 | K6: https://www.elnuevosiglo.com.co/nacion/2013-personas-permanecen-en-albergues-tras-terremoto-en-colombia | L6: Verificada (consulta 5-oct-2026) | M6: 3 albergues | N6: 2.7
A7: Cali | B7: Valle del Cauca | C7: 192 | D7: 2026-08-18 | E7: 8 | F7: personas en albergues en la fecha | G7: 45951 | H7: 23.932813 | I7: F14 | J7: El Nuevo Siglo, 18-ago-2026 | K7: https://www.elnuevosiglo.com.co/nacion/2013-personas-permanecen-en-albergues-tras-terremoto-en-colombia | L7: Verificada (consulta 5-oct-2026) | M7: 2 albergues | N7: 0.42
A8: Armenia | B8: Quindío | C8: 135 | D8: 2026-08-18 | E8: 8 | F8: personas en albergues en la fecha | G8: 13654 | H8: 10.114074 | I8: F14 | J8: El Nuevo Siglo, 18-ago-2026 | K8: https://www.elnuevosiglo.com.co/nacion/2013-personas-permanecen-en-albergues-tras-terremoto-en-colombia | L8: Verificada (consulta 5-oct-2026) | M8: 1 albergue | N8: 0.99
A9: Dosquebradas | B9: Risaralda | C9: 400 | D9: 2026-08-10 a 2026-09-27 | E9: 1-48 | F9: promedio de personas alojadas durante la contingencia | G9: 9136 | H9: 2.284 | I9: F15 | J9: El Blog del Ministro, 29-sep-2026 | K9: https://www.elblogdelministro.com/2026/09/dosquebradas-unifica-alojamientos.html | L9: Verificada (consulta 5-oct-2026) | M9: Promedio de 118 familias y 400 personas en los primeros 48 días; el 27-sep quedaban 28 familias (45 personas) | N9: 4.38

Sheet Control_140_160km
A1: Verificación adicional en Google Maps — pares OSRM de 140 a 160 km (48 pares, 5-oct-2026)
A2: No reemplazan a OSRM en la matriz final (12 consultas muestran cierres viales temporales); se usan como control y sensibilidad.
A4: id_demanda | B4: id_sitio | C4: municipio_origen | D4: sitio_destino | E4: km_OSRM | F4: km_Google_Maps | G4: grupo | H4: observacion_ruta | I4: url_consulta | J4: fecha_consulta | K4: razon_Google_OSRM | L4: factible_OSRM | M4: factible_Google
A5: D66001 | B5: C05 | C5: Pereira | D5: Guadalajara de Buga | E5: 141.912 | F5: 143 | G5: franja 140-160 km (verificación 5-oct-2026) | H5: Ruta más rápida, tráfico habitual | I5: https://www.google.com/maps/dir/4.804985,-75.719711/3.900736,-76.298979/data=!4m2!4m1!3e0?hl=es | J5: 2026-10-05 | K5: 1.008 | L5: 1 | M5: 1
A6: D66001 | B6: C11 | C6: Pereira | D6: Guacarí | E6: 159.36 | F6: 160 | G6: franja 140-160 km (verificación 5-oct-2026) | H6: Ruta más rápida, tráfico habitual | I6: https://www.google.com/maps/dir/4.804985,-75.719711/3.761815,-76.330911/data=!4m2!4m1!3e0?hl=es | J6: 2026-10-05 | K6: 1.004 | L6: 1 | M6: 1
A7: D76109 | B7: C06 | C7: Buenaventura | D7: Candelaria | E7: 140.776 | F7: 142 | G7: franja 140-160 km (verificación 5-oct-2026) | H7: Ruta más rápida según el tráfico del momento | I7: https://www.google.com/maps/dir/3.875708,-77.01074/3.408354,-76.346519/data=!4m2!4m1!3e0?hl=es | J7: 2026-10-05 | K7: 1.009 | L7: 1 | M7: 1
A8: D76109 | B8: C08 | C8: Buenaventura | D8: Florida | E8: 154.894 | F8: 157 | G8: franja 140-160 km (verificación 5-oct-2026) | H8: Ruta más rápida según el tráfico del momento | I8: https://www.google.com/maps/dir/3.875708,-77.01074/3.324118,-76.234199/data=!4m2!4m1!3e0?hl=es | J8: 2026-10-05 | K8: 1.014 | L8: 1 | M8: 1
A9: D63001 | B9: C09 | C9: Armenia | D9: El Cerrito | E9: 144.638 | F9: 142 | G9: franja 140-160 km (verificación 5-oct-2026) | H9: Ruta más rápida, tráfico habitual | I9: https://www.google.com/maps/dir/4.53598,-75.680786/3.684229,-76.311972/data=!4m2!4m1!3e0?hl=es | J9: 2026-10-05 | K9: 0.982 | L9: 1 | M9: 1
A10: D63001 | B10: C12 | C10: Armenia | D10: Ginebra | E10: 147.326 | F10: 143 | G10: franja 140-160 km (verificación 5-oct-2026) | H10: Ruta más rápida, tráfico habitual | I10: https://www.google.com/maps/dir/4.53598,-75.680786/3.724181,-76.268068/data=!4m2!4m1!3e0?hl=es | J10: 2026-10-05 | K10: 0.971 | L10: 1 | M10: 1
A11: D63001 | B11: C14 | C11: Armenia | D11: Supía | E11: 151.364 | F11: 143 | G11: franja 140-160 km (verificación 5-oct-2026) | H11: Ruta más rápida ahora: evita cortes de carretera en Cra. 19 (cierre temporal el 5-oct-2026) | I11: https://www.google.com/maps/dir/4.53598,-75.680786/5.446843,-75.64966/data=!4m2!4m1!3e0?hl=es | J11: 2026-10-05 | K11: 0.945 | L11: 1 | M11: 1
A12: D66170 | B12: C05 | C12: Dosquebradas | D12: Guadalajara de Buga | E12: 145.575 | F12: 147 | G12: franja 140-160 km (verificación 5-oct-2026) | H12: Ruta más rápida, tráfico habitual | I12: https://www.google.com/maps/dir/4.833131,-75.675371/3.900736,-76.298979/data=!4m2!4m1!3e0?hl=es | J12: 2026-10-05 | K12: 1.01 | L12: 1 | M12: 1
A13: D66682 | B13: C05 | C13: Santa Rosa de Cabal | D13: Guadalajara de Buga | E13: 155.968 | F13: 158 | G13: franja 140-160 km (verificación 5-oct-2026) | H13: Ruta más rápida, tráfico habitual | I13: https://www.google.com/maps/dir/4.876271,-75.623268/3.900736,-76.298979/data=!4m2!4m1!3e0?hl=es | J13: 2026-10-05 | K13: 1.013 | L13: 1 | M13: 1
A14: D66682 | B14: C15 | C14: Santa Rosa de Cabal | D14: Aguadas | E14: 156.142 | F14: 159 | G14: franja 140-160 km (verificación 5-oct-2026) | H14: Ruta más rápida según el tráfico del momento | I14: https://www.google.com/maps/dir/4.876271,-75.623268/5.610244,-75.45487/data=!4m2!4m1!3e0?hl=es | J14: 2026-10-05 | K14: 1.018 | L14: 1 | M14: 1
A15: D63594 | B15: C05 | C15: Quimbaya | D15: Guadalajara de Buga | E15: 140.683 | F15: 142 | G15: franja 140-160 km (verificación 5-oct-2026) | H15: Ruta más rápida, tráfico habitual | I15: https://www.google.com/maps/dir/4.624387,-75.765074/3.900736,-76.298979/data=!4m2!4m1!3e0?hl=es | J15: 2026-10-05 | K15: 1.009 | L15: 1 | M15: 1
A16: D63594 | B16: C11 | C16: Quimbaya | D16: Guacarí | E16: 158.131 | F16: 142 | G16: franja 140-160 km (verificación 5-oct-2026) | H16: Ruta más rápida según el tráfico del momento | I16: https://www.google.com/maps/dir/4.624387,-75.765074/3.761815,-76.330911/data=!4m2!4m1!3e0?hl=es | J16: 2026-10-05 | K16: 0.898 | L16: 1 | M16: 1
... A52: D63130 | B52: C14 | C52: Calarcá | D52: Supía | E52: 149.409 | F52: 143 | G52: franja 140-160 km (verificación 5-oct-2026) | H52: Ruta más rápida según el tráfico del momento | I52: https://www.google.com/maps/dir/4.520982,-75.646085/5.446843,-75.64966/data=!4m2!4m1!3e0?hl=es | J52: 2026-10-05 | K52: 0.957 | L52: 1 | M52: 1

Sheet Calidad_datos
A1: Calidad de datos — PASS / WARNING / FAIL (generada por tools/calidad_datos.py)
A2: FAIL = rompe un requisito del enunciado o una regla de construcción (objetivo: 0). WARNING = debilidad conocida y declarada.
A4: id | B4: area | C4: prueba | D4: nivel_si_no_cumple | E4: resultado | F4: detalle
